Workbook

Sheet Owner logic - current
A1: For owner/assignee on an elevation, what we need is to know who is actually working it, but for dealer community, they also have a backup contact that is added.
A3: Notes:
A4: This is current functionality, so SFDC handups are within Salesforce and being directly worked by the teams in SF. SFDC Handup ≠ SFDC Elevation (SFDC Elevation in MSD will be a new handup type)
A5: Manual Handups today are used for Dealer Resolution, Dealer Elevation and Email Handups
A6: Field | B6: Description
A7: Handup Owner | B7: SFDC: This is the person working the handup
B8: Manual/SNOW: This is the person who opened the handup (not relevant)
A9: Assignment Group | B9: Team working the case (different assignment group tables per handup type)
A10: Assignee | B10: Manual Only: This is a contact lookup field. If the handup partner is not a contact, we can't use this field (assignee or assignee email are required- one, not both)
A11: Assignee Email | B11: Manual Only: Email Address of the primary handup contact
A12: Assignee Name | B12: Manual Only: Name of primary handup contact
A13: Additional Email | B13: Manual Only: Email Address of secondary handup contact (used on dealer resolution handups)
A14: Additional Name | B14: Manual Only: Name of secondary handup contact (used on dealer resolution handups)

Sheet D365-ServiceNow
A1: Field | B1: Field Type | C1: Notes | D1: D365 Schema Field | E1: ServiceNow Field | F1: SNOW - Format (if Any) | G1: SNOW - Default Value (IF any)
A2: Subject | B2: Text | D2: title
A3: Service Type | B3: Picklist | C3: Service Request Incident | D3: cat_servicetype
A4: Service | B4: Lookup | C4: Sync'd from ServiceNow | D4: cat_serivce | E4: business_service
A5: Assignment Group | B5: Lookup | D5: cat_assignmentgroupid | E5: assignment_group
A6: Priority | B6: Picklist | C6: Automated - matches parent case, but can be changed | D6: prioritycode | E6: priority | G6: 4
A7: Status | B7: Text | C7: Automated | D7: statecode | E7: state | G7: 1
A8: Description | B8: Text | D8: description | E8: description
A9: Handup Reason
A10: Tracking Number | D10: cat_trackingnumber
A11: External Link | D11: cat_externallink
A12: Integration Error Message | D12: cat_integrationerrormessage
A13: Skip Integration Re-Process | B13: Checkbox | D13: cat_skipintegrationreprocess
A14: Integrated Ticket Status | B14: Lookup | C14: Populates the status of the Handup from the integrated system | D14: cat_integratedticketstatus
A15: Skip Support Ticket | B15: Checkbox | D15: cat_skipsupportticket
A16: Resolution Notes | B16: Text | D16: cat_caseresolutionnote | E16: close_notes
A17: Attachments / Files
A18: Handup Age | B18: Calculated Field | D18: caseage
A19: Handup SLA | B19: Calculated Field | C19: Not a field we have today but SLA for Handup is different than the case age. Let's discuss | D19: No Field in D365 Case Entity
A20: Handup Type | B20: Option | D20: cat_elevationtype
A21: Created By | B21: Lookup | C21: Automated | D21: createdby | E21: sys_created_by
A22: Last Modified By | B22: Lookup | C22: Automated | D22: modifiedby | E22: sys_updated_by
A23: Contact Name | B23: Text | D23: cat_contactname
A24: Contact | B24: Lookup for Contact Entity | D24: primarycontactid
A25: Contact Phone Number | B25: Phone Number | C25: Contact Entity | D25: address1_telephone1
A26: Contact Email Address | B26: email | C26: Contact Entity | D26: emailaddress1
A27: Machine/Asset | B27: Text | D27: cat_machine
A28: Machine S/N | B28: Text | D28: cat_machinesn
A29: Dealer / Dealer Code | B29: Text | D29: cat_dealercode
A30: Dealer Resolution | B30: Multi Line Text | D30: cat_dealerresolution
A31: Product Technology | B31: Look Up | C31: (from case) | D31: productid
A32: Handup ID | B32: Text | C32: (Handup name) | D32: cat_elevationid
A33: Case Number (Hand Number) | B33: Auto Number | C33: (original/parent case) | D33: ticketnumber | E33: correlation_display
A34: Handup Owner | D34: ownerid
A35: Contact City | B35: Text | C35: Contact Entity | D35: address1_city
A36: Contact State | B36: Text | C36: Contact Entity | D36: address1_stateorprovince
A37: Zip Code | B37: Text | C37: Contact Entity | D37: address1_postalcode
A38: Assignee Email | B38: Email | D38: cat_assigneeemail
A39: Assignee Name | B39: Text | D39: cat_assigneename | E39: assigned_to
A40: Additional Assignee | B40: Text | D40: cat_additionalassigneename
...

Sheet Fields by Type
A1: Field | B1: Field Type | C1: Notes | D1: Manual | E1: Dynamics | F1: Dealer Customer Resolution | G1: Dealer Consulation | H1: ServiceNow | I1: Salesforce | J1: HC Visibility (for Dealer Handups only) | K1: D365 Field | L1: Clarification required
A2: Subject | B2: Text | D2: (Required on Email) | F2: - | G2: - | H2: Required | I2: Required (maps to title) | J2: Yes | K2: OOTB | L2: subject
A3: Service Type | B3: Picklist | C3: Service Request Incident | D3: NA | E3: NA | F3: NA | G3: NA | H3: Required | I3: NA | K3: Custom | L3: Request picklist values? 7/7/2026 (POD 1): Handup Type is equal to Service Type? if different then type of Service Type?
A4: Service | B4: Lookup | C4: Sync'd from ServiceNow | D4: NA | E4: NA | F4: NA | G4: NA | H4: Required | I4: NA | K4: Custom? | L4: Lookup to which object/entity? i.e. 11541 Data migration team will handle 7/2/2026 (business ): Service is the platform, service, UI, system, etc. and assignment group is the team working it. Only service now has assignment group and service ). For sfdc there is just 1 assignment group
A5: Assignment Group | B5: Lookup | C5: Required - advisor will select it manually just for tracking purpose. These assignement groups will be added manually | D5: Required - advisor will select it manually just for tracking purpose. These assignement groups will be added manually | E5: Required - advisor will select it manually just for tracking purpose | F5: Required | G5: Required | H5: Required | I5: Required | L5: Lookup to which object/entity? Data migration team will handle. Lookup to the team. Assignment group is used only in service now . SFDC will have just 1 AG- will pull from a different table.(dealer collaboration community team)
A6: Priority | B6: Picklist | C6: Automated - matches parent case, but can be changed. Apply to all handup type | D6: Required | E6: Required | F6: Automated and Required | G6: Automated and Required | H6: Required | I6: Required | K6: OOTB | L6: OOTB Values
A7: Status | B7: Picklist | C7: Automated / Manual - Default as "New" | D7: Required- Default as New | E7: Required | F7: Required | G7: Required | H7: Required | I7: Required | J7: Yes | K7: OOTB | L7: status - values coming from SNOW or SFDC . Can be a text field
A8: Description | B8: Text | C8: description will be entered manually be advisors | D8: Required | E8: Required | F8: Required | G8: Required | H8: Required | I8: Required | J8: Yes | K8: OOTB | L8: description
A9: External Link | C9: URL to snow and Salesforce tickets. NA for others | D9: No | E9: No | F9: NA | G9: NA | H9: Automated | I9: Automated | K9: Custom | L9: URL? should we open on click
A10: Integration Error Message | D10: No | E10: No | F10: NA | G10: NA | H10: Automated | I10: Automated | K10: Custom?
A11: Skip Integration Re-Process | B11: Checkbox | D11: No | E11: No | F11: NA | G11: NA | H11: Automated (can be manually unchecked) | I11: Automated | K11: Custom | L11: Request the details on automated process as it is checkbox. This and previous field used to to send back or not if a error happens in integration EX: assignment group reassigned - SC can you build on this
A12: Integrated Ticket Status | B12: Lookup text | C12: SNOW or CRMi Status . Populates the status of the Handup from the integrated system | D12: No | E12: No | F12: NA | G12: NA | H12: Automated | I12: Automated | K12: Custom? | L12: What will be the values? Since it is lookup field which object / entity to look for? If automated, cant we keep it a text field? This field holds Status on service now and SFDC. Will be a text field . Can be used to mark Handup as resolved. If resolved by dealer then status on child case = Resolved By Dealer For everyone else it is resolution Provided. 7/7/2026 (POD 1): we have made it as choice (Yes/No), if not this then what will be the other values for choice?
A13: Skip Support Ticket | B13: Checkbox | C13: associated with error processing . can be used by new integration (if needed) to trigger manual action . It will alert the dev team | D13: No | E13: No | F13: NA | G13: NA | H13: Automated | I13: Automated | K13: Custom | L13: Purpose? What is the logic of automation? If an error happens this field can be used to manully retrigger the process. Dependent on the final solution cap team builds.
A14: Resolution Notes | B14: Text | D14: Required to close | E14: Required to close | F14: Required to Close | G14: Required to close | H14: Required to Close (copy and append Resolution from SNOW) | J14: On Resolution Details Tab | L14: text field holding the description of the resolution in SFDC or SNOW /Manual . Editable for all , notes from sfdc, snow gets appended to the current comments
A15: Attachments / Files | C15: If there are attachments on case then advisor can pick one or more attachment and copy that to the child handup. This is a manual action. Custom solution was built to enable this feature | D15: Optional | E15: Optional | F15: Optional | G15: Optional | H15: Optional - sync'd between systems | I15: Optional - sync'd between systems | K15: Notes
A16: Handup Age | B16: Calculated Field | C16: Does not gets carried over from parent case. Handup age is a field on the handup/child case record | D16: Automated | E16: Automated | F16: Automated | G16: Automated | H16: Automated | I16: Automated | K16: OOTB | L16: Case Age ( open to close )
A17: Handup Case SLA | B17: Calculated Field | C17: Show the SLA running at the parent case . May throw technical challenge. need to investigate. Can we use copilot to show the latest case SLA | D17: Automated | E17: Automated | F17: Automated | G17: Automated | H17: Automated | I17: Automated | K17: ? | L17: exclude certain statuses and calcualte teht ime spent on the Handup
A18: Handup Type | B18: Option | C18: as shown on header row | D18: Automated | E18: Automated | F18: Automated | G18: Automated | H18: Automated | I18: Automated | K18: Custom? | L18: Values? Manual. SFDC. SNOW How it is being updates
A19: Created By | C19: deafulted to the user who creates the hanup | D19: Automated | E19: Automated | F19: Automated | G19: Automated | H19: Automated | I19: Automated | L19: OOTB field
A20: Last Modified By | C20: Automated | D20: Automated | E20: Automated | F20: Automated | G20: Automated | H20: Automated | I20: Automated | L20: OOTB field
A21: Contact Name | D21: No | E21: No | F21: Automated from Case if Customer Persona | G21: Automated from Case if Customer Persona Do not display on Dealer/Internal Persona | H21: No | I21: No | J21: Customer Requester Only | L21: Related to Contact record. Populate from Requested For if there is a contact else populate it from requested by - fields 24 - 26) 7/7/2026 (POD 1): This field is being mapped to contact entity and we do not plan to create a seperate field for it, is it acceptable or do you require us to create this field?
A22: Contact Phone Number | D22: No | E22: No | F22: Automated from Case if Customer Persona | G22: Automated from Case if Customer Persona Do not display on Dealer/Internal Persona | H22: No | I22: No | J22: Customer Requester Only | L22: Related to Contact record 7/7/2026 (POD 1): This field is being mapped to contact entity and we do not plan to create a seperate field for it, is it acceptable or do you require us to create this field?
A23: Contact Email Address | D23: No | E23: No | F23: Automated from Case if Customer Persona | G23: Automated from Case if Customer Persona Do not display on Dealer/Internal Persona | H23: No | I23: No | J23: Customer Requester Only | L23: Related to Contact record 7/7/2026 (POD 1): This field is being mapped to contact entity and we do not plan to create a seperate field for it, is it acceptable or do you require us to create this field?
A24: Machine/Asset | D24: No | E24: No | F24: Automated from Case if Customer Persona | G24: Automated from Case if Customer Persona Do not display on Dealer/Internal Persona | H24: No | I24: No | L24: Will it come from Case or Asset? If Asset in case of multi asset scenario, how will this work? 7/7/2026 (POD 1): These are two different fields? and what are the type of Machine and Asset field?
A25: Machine S/N | D25: No | E25: No | F25: Automated from Case if Customer Persona | G25: Automated from Case if Customer Persona Do not display on Dealer/Internal Persona | H25: No | I25: No | L25: Will it come from Case or Asset? If Asset in case of multi asset scenario, how will this work? 7/7/2026 (POD 1):What is Machine S/N Type?
A26: Dealer / Dealer Code | D26: No | E26: No | F26: Automated from Case if Customer Persona else will be filled in manually by advisor | G26: Lookup | H26: No | I26: No | J26: Yes
A27: Dealer Resolution | D27: No | E27: No | F27: Required to Close | G27: No | H27: No | I27: No
A28: Product Technology | C28: (from case)- just the product technology | D28: Automated | E28: Automated | F28: Automated | G28: Automated | H28: Automated | I28: Automated | J28: Yes
A29: Handup ID Number | C29: (Handup name) - OOB case number :case/hanup number . generates automatically. Will be send to service now and salesforce appended in text . This field will be used on email subject line | D29: Automated | E29: Automated | F29: Automated | G29: Automated | H29: Automated | I29: Automated | J29: Yes | K29: Custom | L29: Request if any specific format to be followed? Unique child case / Handup number 7/7/2026 (POD 1): Is Case Number and Handup ID same?
A30: Parent Case Number | C30: (original/parent case) | D30: Automated | E30: Automated | F30: Automated | G30: Automated | H30: Automated | I30: Automated | K30: OOTB | L30: Format will be same as original Case?actual case that was submitted . parent case number . starts with TST , ahndup starts with different prefix
A31: Handup Owner | C31: Only Dynamics Handup Type will be sent to queue to be picked by the teams . Manual handup will not be sent to queue. Dealer Consultation ,Dealer Customer resolution- stays with the person who created the handup. Does not go to queue. Service Now /Salesforce - stays with the person who created it | D31: Automated | E31: Automated | F31: Automated | G31: Automated | H31: Automated | I31: Automated | J31: Yes | K31: OOTB | L31: Owner. Will this be case Owner or New owner to which Handup assigned to?
A32: Contact City | D32: No | E32: No | F32: Automated from Case if Customer Persona | G32: Automated from Case if Customer Persona Do not display on Dealer/Internal Persona | H32: No | I32: No | J32: Customer Requester Only | L32: Related to Contact record
A33: Contact State | D33: No | E33: No | F33: Automated from Case if Customer Persona | G33: Automated from Case if Customer Persona Do not display on Dealer/Internal Persona | H33: No | I33: No | J33: Customer Requester Only | L33: Related to Contact record
A34: Zip Code | D34: No | E34: No | F34: Automated from Case if Customer Persona | G34: Automated from Case if Customer Persona Do not display on Dealer/Internal Persona | H34: No | I34: No | J34: Customer Requester Only | L34: Related to Contact record
A35: Assignee Email | D35: Required | E35: No | F35: Required | G35: Required | J35: Yes | K35: Custom | L35: Do we need the field. 7/14/2026 (Saurabh) - yes we need this field to be created locally in dynamics. If there is any notification we will be using the email popualted on field to send the notification.
A36: Assignee Name | B36: Text | D36: Required | E36: No | F36: Required | G36: Required
A37: Additional Assignee | D37: Optional | E37: No | F37: Optional | G37: Optional | J37: Yes | L37: 8/7/2026 (POD 1): Is "Assignee to other" and Assignee Email same?
A38: Additional Email | D38: Optional | E38: No | F38: Optional | G38: Optional | J38: Yes | K38: Custom | L38: 7/7/2026 (POD 1): Additional email 1 and Additional email 2 is available in case, do you want us to create new field 'Additional email' ?
A39: Handup Assignee | F39: Lookup | G39: Lookup - Contact Record | J39: Yes | L39: How it is different than Owner? It will be a lookup to user? 7/7/2026 (POD 1): Handup owner and Handup Assignee are different field? 7/9/2026 - Saurabh - Handup Owner is the Internal Dynamcis User whereas Handup Assignee is the contact lookup . When discussing contact repo solution can we find a way to bring in the contacts easily from helios . Dealers will be using this field to internally reassign the Handup to a different user from their dealership (from tiffani) Manual Only: This is a contact lookup field. If the handup partner is not a contact, we can't use this field (assignee or assignee email are required- one, not both)
A40: Action Requested | B40: Text | F40: Required | G40: Required | J40: Yes | L40: What is the data type? 7/7/2026 (POD 1): Need Optionset value for Action Requested
...

Sheet SF to D365 Handup Types
A1: Current | B1: Future | C1: Assignment Group | D1: Notes
A2: Manual | B2: Manual | C2: Not = Dealer Group
A3: Manual | B3: Dealer Consulation | C3: Dealer Group | D3: Non-eComm Case
A4: Manual | B4: Dealer Customer Resolution | C4: Dealer Group | D4: eCommerce Case
A5: SFDC | B5: Dynamics | C5: Not = Dealer Collaboration Tier 2 Group
A6: SFDC | B6: Salesforce | C6: Dealer Collaboration Tier 2 Group
A7: ServiceNow | B7: ServiceNow

Sheet Assignment Groups - Int & Ext
A1: SF Assignment Group Type | B1: SF Assignment Group Name | C1: Create? | D1: SE | E1: D365 Assignment Group Type | F1: D365 Assignment Group Name | G1: Notes | H1: Column1 | J1: Note: ServiceNow Assignment Groups will sync through the integration | L1: Refer to SF to D365 Handup Types | P1: KPM send no's to Hari - "no recreate"
A2: SFDC Handup | B2: Cat Rental Tier 2 Group | C2: No | D2: Stacy / Julia | E2: X | F2: Retired | G2: Check with Stacy and Julia | H2: =IFERROR(VLOOKUP(Table3[[#This Row],[SF Assignment Group Name]],'Assignment Group Usage'!B:D,3,FALSE),0) -> 22
A3: SFDC Handup | B3: DMT Approval Group | C3: No | E3: X | F3: Retired | G3: Internal Process - DMT retired for CCID management | H3: =IFERROR(VLOOKUP(Table3[[#This Row],[SF Assignment Group Name]],'Assignment Group Usage'!B:D,3,FALSE),0) -> 1
A4: SFDC Handup | B4: CCS SOS T2 Group | C4: No | E4: X | F4: Retired | G4: No longer used | H4: =IFERROR(VLOOKUP(Table3[[#This Row],[SF Assignment Group Name]],'Assignment Group Usage'!B:D,3,FALSE),0) -> 13
A5: SFDC Handup | B5: eCommerce Dealer Escalation Group | C5: No | E5: X | F5: Retired | G5: Not used in 2026. | H5: =IFERROR(VLOOKUP(Table3[[#This Row],[SF Assignment Group Name]],'Assignment Group Usage'!B:D,3,FALSE),0) -> 17
A6: Manual Handup | B6: Managed Account Group | C6: No | E6: X | F6: Retired | G6: Not used in 2026. | H6: =IFERROR(VLOOKUP(Table3[[#This Row],[SF Assignment Group Name]],'Assignment Group Usage'!B:D,3,FALSE),0) -> 11
A7: SFDC Handup | B7: Data Product Mgmt T2 Group | C7: No | E7: X | F7: Retired | G7: Not used in 2026. | H7: =IFERROR(VLOOKUP(Table3[[#This Row],[SF Assignment Group Name]],'Assignment Group Usage'!B:D,3,FALSE),0) -> 10
A8: SFDC Handup | B8: Foresight CM Group | C8: No | E8: X | F8: Retired | G8: Not used in 2026. | H8: =IFERROR(VLOOKUP(Table3[[#This Row],[SF Assignment Group Name]],'Assignment Group Usage'!B:D,3,FALSE),0) -> 3
A9: Manual Handup | B9: EU Data Group | C9: No | E9: X | F9: Retired | G9: Not used in 2026. | H9: =IFERROR(VLOOKUP(Table3[[#This Row],[SF Assignment Group Name]],'Assignment Group Usage'!B:D,3,FALSE),0) -> 2
A10: Manual Handup | B10: BaaS Tier 2 Group | C10: No | E10: X | F10: Retired | G10: Not used in 2026. | H10: =IFERROR(VLOOKUP(Table3[[#This Row],[SF Assignment Group Name]],'Assignment Group Usage'!B:D,3,FALSE),0) -> 1
A11: Manual Handup | B11: Cat Inspect API Approval Group | C11: No | E11: X | F11: Retired | G11: Not used in 2026. | H11: =IFERROR(VLOOKUP(Table3[[#This Row],[SF Assignment Group Name]],'Assignment Group Usage'!B:D,3,FALSE),0) -> 1
A12: SFDC Handup | B12: Cat Technology Monitoring Group | C12: No | E12: X | F12: Retired | G12: Not used in 2026. | H12: =IFERROR(VLOOKUP(Table3[[#This Row],[SF Assignment Group Name]],'Assignment Group Usage'!B:D,3,FALSE),0) -> 1
A13: Manual Handup | B13: Manual Test Record | C13: No | E13: X | F13: Retired | G13: Not used in 2026. | H13: =IFERROR(VLOOKUP(Table3[[#This Row],[SF Assignment Group Name]],'Assignment Group Usage'!B:D,3,FALSE),0) -> 1
A14: Manual Handup | B14: Mining | C14: No | E14: X | F14: Retired | G14: Not used in 2026. | H14: =IFERROR(VLOOKUP(Table3[[#This Row],[SF Assignment Group Name]],'Assignment Group Usage'!B:D,3,FALSE),0) -> 1
... A69: Manual Handup | B69: Dealer Services Group | C69: No | E69: X | F69: Retired | G69: Transferred to SFDC group | H69: =IFERROR(VLOOKUP(Table3[[#This Row],[SF Assignment Group Name]],'Assignment Group Usage'!B:D,3,FALSE),0) -> 2
A70: SFDC Handup | B70: Soft Blocks Group | C70: No | E70: X | F70: Retired | H70: =IFERROR(VLOOKUP(Table3[[#This Row],[SF Assignment Group Name]],'Assignment Group Usage'!B:D,3,FALSE),0) -> 626
A71: Manual Handup | B71: Dealer Collaboration Community Group | C71: No | D71: Kath | E71: X | F71: Retired | H71: =IFERROR(VLOOKUP(Table3[[#This Row],[SF Assignment Group Name]],'Assignment Group Usage'!B:D,3,FALSE),0) -> 25
A72: Manual Handup | B72: Cat Central Group | C72: No | E72: X | F72: Retired | H72: =IFERROR(VLOOKUP(Table3[[#This Row],[SF Assignment Group Name]],'Assignment Group Usage'!B:D,3,FALSE),0) -> 1
A73: Manual Handup | B73: DSP Group | C73: No | E73: X | F73: Retired | H73: =IFERROR(VLOOKUP(Table3[[#This Row],[SF Assignment Group Name]],'Assignment Group Usage'!B:D,3,FALSE),0) -> 1
A74: Manual Handup | B74: Specsizer Group | C74: No | D74: Carita / Lauren | F74: Retired | H74: =IFERROR(VLOOKUP(Table3[[#This Row],[SF Assignment Group Name]],'Assignment Group Usage'!B:D,3,FALSE),0) -> 24
A75: Manual Handup | B75: VST Group | C75: No | D75: Carita / Lauren | F75: Retired | G75: Ask Carita and Lauren | H75: =IFERROR(VLOOKUP(Table3[[#This Row],[SF Assignment Group Name]],'Assignment Group Usage'!B:D,3,FALSE),0) -> 1
A76: Manual Handup | B76: Cat Inspect Group | C76: No | D76: Kath | F76: Retired | H76: =IFERROR(VLOOKUP(Table3[[#This Row],[SF Assignment Group Name]],'Assignment Group Usage'!B:D,3,FALSE),0) -> 1
C77: Yes | D77: Kath / Lauren | E77: Dynamics | F77: ACE | G77: new handup for ace.cat.com | H77: =IFERROR(VLOOKUP(Table3[[#This Row],[SF Assignment Group Name]],'Assignment Group Usage'!B:D,3,FALSE),0) -> 0
A78: Manual Handup | B78: API Group | C78: Yes | D78: Lauren | E78: Manual | F78: API | H78: =IFERROR(VLOOKUP(Table3[[#This Row],[SF Assignment Group Name]],'Assignment Group Usage'!B:D,3,FALSE),0) -> 7
A79: Manual Handup | B79: Billing Group | C79: Yes | D79: Mike | E79: Manual | F79: Billing T2 | H79: =IFERROR(VLOOKUP(Table3[[#This Row],[SF Assignment Group Name]],'Assignment Group Usage'!B:D,3,FALSE),0) -> 14
A80: Manual Handup | B80: Bulk CCID Creation Group | C80: Yes | D80: Mike | E80: Manual | F80: Bulk CCID Creation | H80: =IFERROR(VLOOKUP(Table3[[#This Row],[SF Assignment Group Name]],'Assignment Group Usage'!B:D,3,FALSE),0) -> 3
A81: SFDC Handup | B81: CAIT: Harvester Tier 2 | C81: Yes | D81: Lauren | E81: Dynamics | F81: CAIT: Harvester T2 | H81: =IFERROR(VLOOKUP(Table3[[#This Row],[SF Assignment Group Name]],'Assignment Group Usage'!B:D,3,FALSE),0) -> 36
A82: SFDC Handup | B82: Cat Central Group | C82: Yes | E82: Dynamics | F82: Cat Central | H82: =IFERROR(VLOOKUP(Table3[[#This Row],[SF Assignment Group Name]],'Assignment Group Usage'!B:D,3,FALSE),0) -> 1
A83: SFDC Handup | B83: Cat Converge - Accenture SI Group | C83: Yes | D83: Luke | E83: Dynamics | F83: Cat Converge - Accenture SI | H83: =IFERROR(VLOOKUP(Table3[[#This Row],[SF Assignment Group Name]],'Assignment Group Usage'!B:D,3,FALSE),0) -> 2
A84: Manual Handup | B84: Cat Foresight Group | C84: Yes | D84: Kath | E84: Manual | F84: Cat Foresight | H84: =IFERROR(VLOOKUP(Table3[[#This Row],[SF Assignment Group Name]],'Assignment Group Usage'!B:D,3,FALSE),0) -> 88
A85: SFDC Handup | B85: Analytics Group | C85: Yes | D85: Darlene | E85: Dynamics | F85: CCS DAS Analytics | G85: (Tiffani Renamed) | H85: =IFERROR(VLOOKUP(Table3[[#This Row],[SF Assignment Group Name]],'Assignment Group Usage'!B:D,3,FALSE),0) -> 22
A86: SFDC Handup | B86: CCS Dealer Services Group | C86: Yes | E86: Dynamics | F86: CCS Dealer Services | H86: =IFERROR(VLOOKUP(Table3[[#This Row],[SF Assignment Group Name]],'Assignment Group Usage'!B:D,3,FALSE),0) -> 8
A87: SFDC Handup | B87: CI Tech T2 Group | C87: Yes | E87: Dynamics | F87: CI Tech T2 | H87: =IFERROR(VLOOKUP(Table3[[#This Row],[SF Assignment Group Name]],'Assignment Group Usage'!B:D,3,FALSE),0) -> 1
A88: SFDC Handup | B88: CSO Group | C88: Yes | D88: Mike | E88: Dynamics | F88: CSO | H88: =IFERROR(VLOOKUP(Table3[[#This Row],[SF Assignment Group Name]],'Assignment Group Usage'!B:D,3,FALSE),0) -> 30
A89: SFDC Handup | B89: Customer Admin Tool T2 Group | C89: Yes | D89: Mike | E89: Dynamics | F89: Customer Admin Tool T2 | H89: =IFERROR(VLOOKUP(Table3[[#This Row],[SF Assignment Group Name]],'Assignment Group Usage'!B:D,3,FALSE),0) -> 167
A90: SFDC Handup | B90: DDC Group | C90: Yes | D90: Mike | E90: Dynamics | F90: DDC | H90: =IFERROR(VLOOKUP(Table3[[#This Row],[SF Assignment Group Name]],'Assignment Group Usage'!B:D,3,FALSE),0) -> 27
A91: SFDC Handup | B91: Dealer Collaboration Tier 2 Group | C91: Yes | D91: Kath | E91: Salesforce | F91: Dealer Collaboration T2 | G91: Will remain on SF and worked through integration | H91: =IFERROR(VLOOKUP(Table3[[#This Row],[SF Assignment Group Name]],'Assignment Group Usage'!B:D,3,FALSE),0) -> 123
A92: Manual Handup | B92: Dealer Group | C92: Yes | D92: Kath | E92: Dealer Handup | F92: Dealer Group | H92: =IFERROR(VLOOKUP(Table3[[#This Row],[SF Assignment Group Name]],'Assignment Group Usage'!B:D,3,FALSE),0) -> 1642
A93: SFDC Handup | B93: DGS Group | C93: Yes | D93: Mike | E93: Dynamics | F93: DGS | H93: =IFERROR(VLOOKUP(Table3[[#This Row],[SF Assignment Group Name]],'Assignment Group Usage'!B:D,3,FALSE),0) -> 8
A94: SFDC Handup | B94: Digital Billing Tier 2 Group | C94: Yes | D94: Mike | E94: Dynamics | F94: Digital Billing T2 | H94: =IFERROR(VLOOKUP(Table3[[#This Row],[SF Assignment Group Name]],'Assignment Group Usage'!B:D,3,FALSE),0) -> 33
...

Sheet CCS Assignment Groups
A1: First Name | B1: Last Name | C1: Assignment Group | D1: Who | E1: Manager
A2: Noah | B2: Rolan | C2: PST Connectivity | D2: Cat | E2: Don Kern
A3: Robert | B3: Hanks | C3: PST Connectivity | D3: Cat | E3: Don Kern
A4: Christian | B4: Merrick | C4: PST Connectivity | D4: Cat | E4: Don Kern
A5: Thomas | B5: Fisher | C5: PST Connectivity | D5: Cat | E5: Don Kern
A6: Michael | B6: Larsen | C6: PST Connectivity | D6: Cat | E6: Don Kern
A7: Brandon | B7: Snead | C7: PST Connectivity | D7: Cat | E7: Don Kern
A8: Kaiden | B8: Love | C8: PST Connectivity | D8: Cat | E8: Don Kern
A9: Marlon | B9: Ball | C9: PST Connectivity | D9: Cat | E9: Don Kern
A10: Tyler | B10: Hasty | C10: PST Connectivity | D10: Cat | E10: Don Kern
A11: John | B11: Ciko | C11: PST Digital | D11: Cat | E11: Jeff Sharp
A12: Jim | B12: Craig | C12: PST Digital | D12: Cat | E12: Jeff Sharp
... A58: James | B58: Alderson | C58: PST M&T | D58: Cat | E58: Sherri Schmidt
C59: CCS DAS Analytics | E59: Derek Blunier
C60: CCS DAS Analytics | E60: Derek Blunier
C61: CCS DAS Analytics | E61: Derek Blunier
C62: CCS DAS Analytics | E62: Derek Blunier
C63: CCS DAS Analytics | E63: Derek Blunier

Sheet T2 Assignment Groups Names
A1: Assignment Group | B1: Manager | C1: First Name | D1: Last Name

Sheet Projects

Sheet Assignment Group Usage
A1: Assignment Group: Type ↑ | B1: Assignment Group Name ↑ | C1: Handup: Created Date ↑ | D1: Record Count
A2: Manual Handup | B2: Anchnet Group | C2: January 2025 | D2: 19 | G2: Assignment Group Counts
C3: February 2025 | D3: 13 | G3: As of 2026-09-01 20:32:19 Central Standard Time/CST • Generated by Tiffani Potter
C4: March 2025 | D4: 50
C5: April 2025 | D5: 33
C6: May 2025 | D6: 51 | G6: Filtered By
C7: June 2025 | D7: 45 | G7: Show: All handups
C8: July 2025 | D8: 59 | G8: Date Field: Handup Created Date equals Current and Previous FY (1/1/2025 to 12/31/2026)
C9: August 2025 | D9: 45
C10: September 2025 | D10: 49
C11: October 2025 | D11: 17
C12: November 2025 | D12: 24
C13: December 2025 | D13: 34
C14: January 2026 | D14: 34
C15: February 2026 | D15: 17
C16: March 2026 | D16: 56
C17: April 2026 | D17: 45
C18: May 2026 | D18: 20
C19: June 2026 | D19: 40
C20: July 2026 | D20: 48
... C22: September 2026 | D22: 3
B23: API Group | C23: March 2025 | D23: 7
C24: April 2025 | D24: 3
C25: May 2025 | D25: 6
C26: June 2025 | D26: 2
C27: July 2025 | D27: 5
C28: October 2025 | D28: 3
C29: December 2025 | D29: 4
C30: January 2026 | D30: 1
C31: February 2026 | D31: 1
C32: March 2026 | D32: 3
C33: May 2026 | D33: 4
C34: June 2026 | D34: 3
C35: July 2026 | D35: 2
C36: August 2026 | D36: 1
B37: BaaS Tier 2 Group | C37: March 2025 | D37: 1
B38: Billing Group | C38: January 2025 | D38: 14
C39: February 2025 | D39: 28
C40: March 2025 | D40: 27
C41: April 2025 | D41: 29
...
